<?xml version="1.0"?>
<robot name="simple_robot">
  <!-- ベースリンク -->
  <link name="base_link">
    <visual>
      <geometry>
        <box size="0.01 0.01 0.01"/>
      </geometry>
      <material name="blue">
        <color rgba="0 0 1 1"/>
      </material>
    </visual>
  </link>
  <joint name="joint0" type="fixed">
    <parent link="base_link"/>
    <child link="link1"/>
    <origin xyz="0 0 0.135" rpy="0 0 0"/>
    <axis xyz="0 0 0"/>
  </joint>
  
  <link name="link1">
    <visual>
      <geometry>
        <mesh filename="package://snake_sim/share/snake_sim/config/model/meshes/simple_snake_link.stl" scale="1 1 1"/>
      </geometry>
      <material name="yellow">
        <color rgba="1 1 0 1"/>
      </material>
    </visual>
    <collision>
      <origin
        xyz="0 0 0"
        rpy="0 0 0" />
      <geometry>
        <mesh
          filename="package://snake_sim/share/snake_sim/config/model/meshes/simple_snake_link.stl" scale="1 1 1"/>
      </geometry>
    </collision>
    <inertial>
      <origin
        xyz="-0.018 0 0"
        rpy="0 0 0" />
      <mass
        value="0.300" />
      <inertia
        ixx="1.732E-04"
        ixy="0.000"
        ixz="0.000"
        iyy="2.871E-04"
        iyz="2.979E-10"
        izz="3.147E-04" />
    </inertial>
  </link>
  <joint name="joint1" type="revolute">
    <parent link="link1"/>
    <child link="link2"/>
    <origin xyz="-0.09 0 0" rpy="1.570796 0 0"/>
    <axis xyz="0 0 1"/>
    <limit lower="-1.57" upper="1.57" effort="9.2" velocity="1.72"/>
  </joint>
  <link name="link2">
    <visual>
      <geometry>
        <mesh filename="package://snake_sim/share/snake_sim/config/model/meshes/simple_snake_link.stl" scale="1 1 1"/>
      </geometry>
      <material name="green">
        <color rgba="0 1 0 1"/>
      </material>
    </visual>
    <collision>
      <origin
        xyz="0 0 0"
        rpy="0 0 0" />
      <geometry>
        <mesh
          filename="package://snake_sim/share/snake_sim/config/model/meshes/simple_snake_link.stl" scale="1 1 1"/>
      </geometry>
    </collision>
    <inertial>
      <origin
        xyz="-0.018 0 0"
        rpy="0 0 0" />
      <mass
        value="0.300" />
      <inertia
        ixx="1.732E-04"
        ixy="0.000"
        ixz="0.000"
        iyy="2.871E-04"
        iyz="2.979E-10"
        izz="3.147E-04" />
    </inertial>
  </link>
  <joint name="joint2" type="revolute">
    <parent link="link2"/>
    <child link="link3"/>
    <origin xyz="-0.09 0 0" rpy="-1.570796 0 0"/>
    <axis xyz="0 0 1"/>
    <limit lower="-1.57" upper="1.57" effort="9.2" velocity="1.72"/>
  </joint>
  <link name="link3">
    <visual>
      <geometry>
        <mesh filename="package://snake_sim/share/snake_sim/config/model/meshes/simple_snake_link.stl" scale="1 1 1"/>
      </geometry>
      <material name="yellow">
        <color rgba="1 1 0 1"/>
      </material>
    </visual>
    <collision>
      <origin
        xyz="0 0 0"
        rpy="0 0 0" />
      <geometry>
        <mesh
          filename="package://snake_sim/share/snake_sim/config/model/meshes/simple_snake_link.stl" scale="1 1 1"/>
      </geometry>
    </collision>
    <inertial>
      <origin
        xyz="-0.018 0 0"
        rpy="0 0 0" />
      <mass
        value="0.300" />
      <inertia
        ixx="1.732E-04"
        ixy="0.000"
        ixz="0.000"
        iyy="2.871E-04"
        iyz="2.979E-10"
        izz="3.147E-04" />
    </inertial>
  </link>
  <joint name="joint3" type="revolute">
    <parent link="link3"/>
    <child link="link4"/>
    <origin xyz="-0.09 0 0" rpy="1.570796 0 0"/>
    <axis xyz="0 0 1"/>
    <limit lower="-1.57" upper="1.57" effort="9.2" velocity="1.72"/>
  </joint>
  <link name="link4">
    <visual>
      <geometry>
        <mesh filename="package://snake_sim/share/snake_sim/config/model/meshes/simple_snake_link.stl" scale="1 1 1"/>
      </geometry>
      <material name="green">
        <color rgba="0 1 0 1"/>
      </material>
    </visual>
    <collision>
      <origin
        xyz="0 0 0"
        rpy="0 0 0" />
      <geometry>
        <mesh
          filename="package://snake_sim/share/snake_sim/config/model/meshes/simple_snake_link.stl" scale="1 1 1"/>
      </geometry>
    </collision>
    <inertial>
      <origin
        xyz="-0.018 0 0"
        rpy="0 0 0" />
      <mass
        value="0.300" />
      <inertia
        ixx="1.732E-04"
        ixy="0.000"
        ixz="0.000"
        iyy="2.871E-04"
        iyz="2.979E-10"
        izz="3.147E-04" />
    </inertial>
  </link>
  <joint name="joint4" type="revolute">
    <parent link="link4"/>
    <child link="link5"/>
    <origin xyz="-0.09 0 0" rpy="-1.570796 0 0"/>
    <axis xyz="0 0 1"/>
    <limit lower="-1.57" upper="1.57" effort="9.2" velocity="1.72"/>
  </joint>
  <link name="link5">
    <visual>
      <geometry>
        <mesh filename="package://snake_sim/share/snake_sim/config/model/meshes/simple_snake_link.stl" scale="1 1 1"/>
      </geometry>
      <material name="yellow">
        <color rgba="1 1 0 1"/>
      </material>
    </visual>
    <collision>
      <origin
        xyz="0 0 0"
        rpy="0 0 0" />
      <geometry>
        <mesh
          filename="package://snake_sim/share/snake_sim/config/model/meshes/simple_snake_link.stl" scale="1 1 1"/>
      </geometry>
    </collision>
    <inertial>
      <origin
        xyz="-0.018 0 0"
        rpy="0 0 0" />
      <mass
        value="0.300" />
      <inertia
        ixx="1.732E-04"
        ixy="0.000"
        ixz="0.000"
        iyy="2.871E-04"
        iyz="2.979E-10"
        izz="3.147E-04" />
    </inertial>
  </link>
  <joint name="joint5" type="revolute">
    <parent link="link5"/>
    <child link="link6"/>
    <origin xyz="-0.09 0 0" rpy="1.570796 0 0"/>
    <axis xyz="0 0 1"/>
    <limit lower="-1.57" upper="1.57" effort="9.2" velocity="1.72"/>
  </joint>
  <link name="link6">
    <visual>
      <geometry>
        <mesh filename="package://snake_sim/share/snake_sim/config/model/meshes/simple_snake_link.stl" scale="1 1 1"/>
      </geometry>
      <material name="green">
        <color rgba="0 1 0 1"/>
      </material>
    </visual>
    <collision>
      <origin
        xyz="0 0 0"
        rpy="0 0 0" />
      <geometry>
        <mesh
          filename="package://snake_sim/share/snake_sim/config/model/meshes/simple_snake_link.stl" scale="1 1 1"/>
      </geometry>
    </collision>
    <inertial>
      <origin
        xyz="-0.018 0 0"
        rpy="0 0 0" />
      <mass
        value="0.300" />
      <inertia
        ixx="1.732E-04"
        ixy="0.000"
        ixz="0.000"
        iyy="2.871E-04"
        iyz="2.979E-10"
        izz="3.147E-04" />
    </inertial>
  </link>
  <joint name="joint6" type="revolute">
    <parent link="link6"/>
    <child link="link7"/>
    <origin xyz="-0.09 0 0" rpy="-1.570796 0 0"/>
    <axis xyz="0 0 1"/>
    <limit lower="-1.57" upper="1.57" effort="9.2" velocity="1.72"/>
  </joint>
  <link name="link7">
    <visual>
      <geometry>
        <mesh filename="package://snake_sim/share/snake_sim/config/model/meshes/simple_snake_link.stl" scale="1 1 1"/>
      </geometry>
      <material name="yellow">
        <color rgba="1 1 0 1"/>
      </material>
    </visual>
    <collision>
      <origin
        xyz="0 0 0"
        rpy="0 0 0" />
      <geometry>
        <mesh
          filename="package://snake_sim/share/snake_sim/config/model/meshes/simple_snake_link.stl" scale="1 1 1"/>
      </geometry>
    </collision>
    <inertial>
      <origin
        xyz="-0.018 0 0"
        rpy="0 0 0" />
      <mass
        value="0.300" />
      <inertia
        ixx="1.732E-04"
        ixy="0.000"
        ixz="0.000"
        iyy="2.871E-04"
        iyz="2.979E-10"
        izz="3.147E-04" />
    </inertial>
  </link>
  <joint name="joint7" type="revolute">
    <parent link="link7"/>
    <child link="link8"/>
    <origin xyz="-0.09 0 0" rpy="1.570796 0 0"/>
    <axis xyz="0 0 1"/>
    <limit lower="-1.57" upper="1.57" effort="9.2" velocity="1.72"/>
  </joint>
  <link name="link8">
    <visual>
      <geometry>
        <mesh filename="package://snake_sim/share/snake_sim/config/model/meshes/simple_snake_link.stl" scale="1 1 1"/>
      </geometry>
      <material name="green">
        <color rgba="0 1 0 1"/>
      </material>
    </visual>
    <collision>
      <origin
        xyz="0 0 0"
        rpy="0 0 0" />
      <geometry>
        <mesh
          filename="package://snake_sim/share/snake_sim/config/model/meshes/simple_snake_link.stl" scale="1 1 1"/>
      </geometry>
    </collision>
    <inertial>
      <origin
        xyz="-0.018 0 0"
        rpy="0 0 0" />
      <mass
        value="0.300" />
      <inertia
        ixx="1.732E-04"
        ixy="0.000"
        ixz="0.000"
        iyy="2.871E-04"
        iyz="2.979E-10"
        izz="3.147E-04" />
    </inertial>
  </link>
  <joint name="joint8" type="revolute">
    <parent link="link8"/>
    <child link="link9"/>
    <origin xyz="-0.09 0 0" rpy="-1.570796 0 0"/>
    <axis xyz="0 0 1"/>
    <limit lower="-1.57" upper="1.57" effort="9.2" velocity="1.72"/>
  </joint>
  <link name="link9">
    <visual>
      <geometry>
        <mesh filename="package://snake_sim/share/snake_sim/config/model/meshes/simple_snake_link.stl" scale="1 1 1"/>
      </geometry>
      <material name="yellow">
        <color rgba="1 1 0 1"/>
      </material>
    </visual>
    <collision>
      <origin
        xyz="0 0 0"
        rpy="0 0 0" />
      <geometry>
        <mesh
          filename="package://snake_sim/share/snake_sim/config/model/meshes/simple_snake_link.stl" scale="1 1 1"/>
      </geometry>
    </collision>
    <inertial>
      <origin
        xyz="-0.018 0 0"
        rpy="0 0 0" />
      <mass
        value="0.300" />
      <inertia
        ixx="1.732E-04"
        ixy="0.000"
        ixz="0.000"
        iyy="2.871E-04"
        iyz="2.979E-10"
        izz="3.147E-04" />
    </inertial>
  </link>
  <joint name="joint9" type="revolute">
    <parent link="link9"/>
    <child link="link10"/>
    <origin xyz="-0.09 0 0" rpy="1.570796 0 0"/>
    <axis xyz="0 0 1"/>
    <limit lower="-1.57" upper="1.57" effort="9.2" velocity="1.72"/>
  </joint>
  <link name="link10">
    <visual>
      <geometry>
        <mesh filename="package://snake_sim/share/snake_sim/config/model/meshes/simple_snake_link.stl" scale="1 1 1"/>
      </geometry>
      <material name="green">
        <color rgba="0 1 0 1"/>
      </material>
    </visual>
    <collision>
      <origin
        xyz="0 0 0"
        rpy="0 0 0" />
      <geometry>
        <mesh
          filename="package://snake_sim/share/snake_sim/config/model/meshes/simple_snake_link.stl" scale="1 1 1"/>
      </geometry>
    </collision>
    <inertial>
      <origin
        xyz="-0.018 0 0"
        rpy="0 0 0" />
      <mass
        value="0.300" />
      <inertia
        ixx="1.732E-04"
        ixy="0.000"
        ixz="0.000"
        iyy="2.871E-04"
        iyz="2.979E-10"
        izz="3.147E-04" />
    </inertial>
  </link>
  <joint name="joint10" type="revolute">
    <parent link="link10"/>
    <child link="link11"/>
    <origin xyz="-0.09 0 0" rpy="-1.570796 0 0"/>
    <axis xyz="0 0 1"/>
    <limit lower="-1.57" upper="1.57" effort="9.2" velocity="1.72"/>
  </joint>
  <link name="link11">
    <visual>
      <geometry>
        <mesh filename="package://snake_sim/share/snake_sim/config/model/meshes/simple_snake_link.stl" scale="1 1 1"/>
      </geometry>
      <material name="yellow">
        <color rgba="1 1 0 1"/>
      </material>
    </visual>
    <collision>
      <origin
        xyz="0 0 0"
        rpy="0 0 0" />
      <geometry>
        <mesh
          filename="package://snake_sim/share/snake_sim/config/model/meshes/simple_snake_link.stl" scale="1 1 1"/>
      </geometry>
    </collision>
    <inertial>
      <origin
        xyz="-0.018 0 0"
        rpy="0 0 0" />
      <mass
        value="0.300" />
      <inertia
        ixx="1.732E-04"
        ixy="0.000"
        ixz="0.000"
        iyy="2.871E-04"
        iyz="2.979E-10"
        izz="3.147E-04" />
    </inertial>
  </link>
  <joint name="joint11" type="revolute">
    <parent link="link11"/>
    <child link="link12"/>
    <origin xyz="-0.09 0 0" rpy="1.570796 0 0"/>
    <axis xyz="0 0 1"/>
    <limit lower="-1.57" upper="1.57" effort="9.2" velocity="1.72"/>
  </joint>
  <link name="link12">
    <visual>
      <geometry>
        <mesh filename="package://snake_sim/share/snake_sim/config/model/meshes/simple_snake_link.stl" scale="1 1 1"/>
      </geometry>
      <material name="green">
        <color rgba="0 1 0 1"/>
      </material>
    </visual>
    <collision>
      <origin
        xyz="0 0 0"
        rpy="0 0 0" />
      <geometry>
        <mesh
          filename="package://snake_sim/share/snake_sim/config/model/meshes/simple_snake_link.stl" scale="1 1 1"/>
      </geometry>
    </collision>
    <inertial>
      <origin
        xyz="-0.018 0 0"
        rpy="0 0 0" />
      <mass
        value="0.300" />
      <inertia
        ixx="1.732E-04"
        ixy="0.000"
        ixz="0.000"
        iyy="2.871E-04"
        iyz="2.979E-10"
        izz="3.147E-04" />
    </inertial>
  </link>
  <joint name="joint12" type="revolute">
    <parent link="link12"/>
    <child link="link13"/>
    <origin xyz="-0.09 0 0" rpy="-1.570796 0 0"/>
    <axis xyz="0 0 1"/>
    <limit lower="-1.57" upper="1.57" effort="9.2" velocity="1.72"/>
  </joint>
  <link name="link13">
    <visual>
      <geometry>
        <mesh filename="package://snake_sim/share/snake_sim/config/model/meshes/simple_snake_link.stl" scale="1 1 1"/>
      </geometry>
      <material name="yellow">
        <color rgba="1 1 0 1"/>
      </material>
    </visual>
    <collision>
      <origin
        xyz="0 0 0"
        rpy="0 0 0" />
      <geometry>
        <mesh
          filename="package://snake_sim/share/snake_sim/config/model/meshes/simple_snake_link.stl" scale="1 1 1"/>
      </geometry>
    </collision>
    <inertial>
      <origin
        xyz="-0.018 0 0"
        rpy="0 0 0" />
      <mass
        value="0.300" />
      <inertia
        ixx="1.732E-04"
        ixy="0.000"
        ixz="0.000"
        iyy="2.871E-04"
        iyz="2.979E-10"
        izz="3.147E-04" />
    </inertial>
  </link>
  <joint name="joint13" type="revolute">
    <parent link="link13"/>
    <child link="link14"/>
    <origin xyz="-0.09 0 0" rpy="1.570796 0 0"/>
    <axis xyz="0 0 1"/>
    <limit lower="-1.57" upper="1.57" effort="9.2" velocity="1.72"/>
  </joint>
  <link name="link14">
    <visual>
      <geometry>
        <mesh filename="package://snake_sim/share/snake_sim/config/model/meshes/simple_snake_link.stl" scale="1 1 1"/>
      </geometry>
      <material name="green">
        <color rgba="0 1 0 1"/>
      </material>
    </visual>
    <collision>
      <origin
        xyz="0 0 0"
        rpy="0 0 0" />
      <geometry>
        <mesh
          filename="package://snake_sim/share/snake_sim/config/model/meshes/simple_snake_link.stl" scale="1 1 1"/>
      </geometry>
    </collision>
    <inertial>
      <origin
        xyz="-0.018 0 0"
        rpy="0 0 0" />
      <mass
        value="0.300" />
      <inertia
        ixx="1.732E-04"
        ixy="0.000"
        ixz="0.000"
        iyy="2.871E-04"
        iyz="2.979E-10"
        izz="3.147E-04" />
    </inertial>
  </link>
  <joint name="joint14" type="revolute">
    <parent link="link14"/>
    <child link="link15"/>
    <origin xyz="-0.09 0 0" rpy="-1.570796 0 0"/>
    <axis xyz="0 0 1"/>
    <limit lower="-1.57" upper="1.57" effort="9.2" velocity="1.72"/>
  </joint>
  <link name="link15">
    <visual>
      <geometry>
        <mesh filename="package://snake_sim/share/snake_sim/config/model/meshes/simple_snake_link.stl" scale="1 1 1"/>
      </geometry>
      <material name="yellow">
        <color rgba="1 1 0 1"/>
      </material>
    </visual>
    <collision>
      <origin
        xyz="0 0 0"
        rpy="0 0 0" />
      <geometry>
        <mesh
          filename="package://snake_sim/share/snake_sim/config/model/meshes/simple_snake_link.stl" scale="1 1 1"/>
      </geometry>
    </collision>
    <inertial>
      <origin
        xyz="-0.018 0 0"
        rpy="0 0 0" />
      <mass
        value="0.300" />
      <inertia
        ixx="1.732E-04"
        ixy="0.000"
        ixz="0.000"
        iyy="2.871E-04"
        iyz="2.979E-10"
        izz="3.147E-04" />
    </inertial>
  </link>
  <joint name="joint15" type="revolute">
    <parent link="link15"/>
    <child link="link16"/>
    <origin xyz="-0.09 0 0" rpy="1.570796 0 0"/>
    <axis xyz="0 0 1"/>
    <limit lower="-1.57" upper="1.57" effort="9.2" velocity="1.72"/>
  </joint>
  <link name="link16">
    <visual>
      <geometry>
        <mesh filename="package://snake_sim/share/snake_sim/config/model/meshes/simple_snake_link.stl" scale="1 1 1"/>
      </geometry>
      <material name="green">
        <color rgba="0 1 0 1"/>
      </material>
    </visual>
    <collision>
      <origin
        xyz="0 0 0"
        rpy="0 0 0" />
      <geometry>
        <mesh
          filename="package://snake_sim/share/snake_sim/config/model/meshes/simple_snake_link.stl" scale="1 1 1"/>
      </geometry>
    </collision>
    <inertial>
      <origin
        xyz="-0.018 0 0"
        rpy="0 0 0" />
      <mass
        value="0.300" />
      <inertia
        ixx="1.732E-04"
        ixy="0.000"
        ixz="0.000"
        iyy="2.871E-04"
        iyz="2.979E-10"
        izz="3.147E-04" />
    </inertial>
  </link>
  <joint name="joint16" type="revolute">
    <parent link="link16"/>
    <child link="link17"/>
    <origin xyz="-0.09 0 0" rpy="-1.570796 0 0"/>
    <axis xyz="0 0 1"/>
    <limit lower="-1.57" upper="1.57" effort="9.2" velocity="1.72"/>
  </joint>
  <link name="link17">
    <visual>
      <geometry>
        <mesh filename="package://snake_sim/share/snake_sim/config/model/meshes/simple_snake_link.stl" scale="1 1 1"/>
      </geometry>
      <material name="yellow">
        <color rgba="1 1 0 1"/>
      </material>
    </visual>
    <collision>
      <origin
        xyz="0 0 0"
        rpy="0 0 0" />
      <geometry>
        <mesh
          filename="package://snake_sim/share/snake_sim/config/model/meshes/simple_snake_link.stl" scale="1 1 1"/>
      </geometry>
    </collision>
    <inertial>
      <origin
        xyz="-0.018 0 0"
        rpy="0 0 0" />
      <mass
        value="0.300" />
      <inertia
        ixx="1.732E-04"
        ixy="0.000"
        ixz="0.000"
        iyy="2.871E-04"
        iyz="2.979E-10"
        izz="3.147E-04" />
    </inertial>
  </link>
  <joint name="joint17" type="revolute">
    <parent link="link17"/>
    <child link="link18"/>
    <origin xyz="-0.09 0 0" rpy="1.570796 0 0"/>
    <axis xyz="0 0 1"/>
    <limit lower="-1.57" upper="1.57" effort="9.2" velocity="1.72"/>
  </joint>
  <link name="link18">
    <visual>
      <geometry>
        <mesh filename="package://snake_sim/share/snake_sim/config/model/meshes/simple_snake_link.stl" scale="1 1 1"/>
      </geometry>
      <material name="green">
        <color rgba="0 1 0 1"/>
      </material>
    </visual>
    <collision>
      <origin
        xyz="0 0 0"
        rpy="0 0 0" />
      <geometry>
        <mesh
          filename="package://snake_sim/share/snake_sim/config/model/meshes/simple_snake_link.stl" scale="1 1 1"/>
      </geometry>
    </collision>
    <inertial>
      <origin
        xyz="-0.018 0 0"
        rpy="0 0 0" />
      <mass
        value="0.300" />
      <inertia
        ixx="1.732E-04"
        ixy="0.000"
        ixz="0.000"
        iyy="2.871E-04"
        iyz="2.979E-10"
        izz="3.147E-04" />
    </inertial>
  </link>
  <joint name="joint18" type="revolute">
    <parent link="link18"/>
    <child link="link19"/>
    <origin xyz="-0.09 0 0" rpy="-1.570796 0 0"/>
    <axis xyz="0 0 1"/>
    <limit lower="-1.57" upper="1.57" effort="9.2" velocity="1.72"/>
  </joint>
  <link name="link19">
    <visual>
      <geometry>
        <mesh filename="package://snake_sim/share/snake_sim/config/model/meshes/simple_snake_link.stl" scale="1 1 1"/>
      </geometry>
      <material name="yellow">
        <color rgba="1 1 0 1"/>
      </material>
    </visual>
    <collision>
      <origin
        xyz="0 0 0"
        rpy="0 0 0" />
      <geometry>
        <mesh
          filename="package://snake_sim/share/snake_sim/config/model/meshes/simple_snake_link.stl" scale="1 1 1"/>
      </geometry>
    </collision>
    <inertial>
      <origin
        xyz="-0.018 0 0"
        rpy="0 0 0" />
      <mass
        value="0.300" />
      <inertia
        ixx="1.732E-04"
        ixy="0.000"
        ixz="0.000"
        iyy="2.871E-04"
        iyz="2.979E-10"
        izz="3.147E-04" />
    </inertial>
  </link>
  <joint name="joint19" type="revolute">
    <parent link="link19"/>
    <child link="link20"/>
    <origin xyz="-0.09 0 0" rpy="1.570796 0 0"/>
    <axis xyz="0 0 1"/>
    <limit lower="-1.57" upper="1.57" effort="9.2" velocity="1.72"/>
  </joint>
  <link name="link20">
    <visual>
      <geometry>
        <mesh filename="package://snake_sim/share/snake_sim/config/model/meshes/simple_snake_link.stl" scale="1 1 1"/>
      </geometry>
      <material name="green">
        <color rgba="0 1 0 1"/>
      </material>
    </visual>
    <collision>
      <origin
        xyz="0 0 0"
        rpy="0 0 0" />
      <geometry>
        <mesh
          filename="package://snake_sim/share/snake_sim/config/model/meshes/simple_snake_link.stl" scale="1 1 1"/>
      </geometry>
    </collision>
    <inertial>
      <origin
        xyz="-0.018 0 0"
        rpy="0 0 0" />
      <mass
        value="0.300" />
      <inertia
        ixx="1.732E-04"
        ixy="0.000"
        ixz="0.000"
        iyy="2.871E-04"
        iyz="2.979E-10"
        izz="3.147E-04" />
    </inertial>
  </link>
  <joint name="joint20" type="revolute">
    <parent link="link20"/>
    <child link="link21"/>
    <origin xyz="-0.09 0 0" rpy="-1.570796 0 0"/>
    <axis xyz="0 0 1"/>
    <limit lower="-1.57" upper="1.57" effort="9.2" velocity="1.72"/>
  </joint>
  <link name="link21">
    <visual>
      <geometry>
        <mesh filename="package://snake_sim/share/snake_sim/config/model/meshes/simple_snake_link.stl" scale="1 1 1"/>
      </geometry>
      <material name="yellow">
        <color rgba="1 1 0 1"/>
      </material>
    </visual>
    <collision>
      <origin
        xyz="0 0 0"
        rpy="0 0 0" />
      <geometry>
        <mesh
          filename="package://snake_sim/share/snake_sim/config/model/meshes/simple_snake_link.stl" scale="1 1 1"/>
      </geometry>
    </collision>
    <inertial>
      <origin
        xyz="-0.018 0 0"
        rpy="0 0 0" />
      <mass
        value="0.300" />
      <inertia
        ixx="1.732E-04"
        ixy="0.000"
        ixz="0.000"
        iyy="2.871E-04"
        iyz="2.979E-10"
        izz="3.147E-04" />
    </inertial>
  </link>
  <joint name="joint21" type="revolute">
    <parent link="link21"/>
    <child link="link22"/>
    <origin xyz="-0.09 0 0" rpy="1.570796 0 0"/>
    <axis xyz="0 0 1"/>
    <limit lower="-1.57" upper="1.57" effort="9.2" velocity="1.72"/>
  </joint>
  <link name="link22">
    <visual>
      <geometry>
        <mesh filename="package://snake_sim/share/snake_sim/config/model/meshes/simple_snake_link.stl" scale="1 1 1"/>
      </geometry>
      <material name="green">
        <color rgba="0 1 0 1"/>
      </material>
    </visual>
    <collision>
      <origin
        xyz="0 0 0"
        rpy="0 0 0" />
      <geometry>
        <mesh
          filename="package://snake_sim/share/snake_sim/config/model/meshes/simple_snake_link.stl" scale="1 1 1"/>
      </geometry>
    </collision>
    <inertial>
      <origin
        xyz="-0.018 0 0"
        rpy="0 0 0" />
      <mass
        value="0.300" />
      <inertia
        ixx="1.732E-04"
        ixy="0.000"
        ixz="0.000"
        iyy="2.871E-04"
        iyz="2.979E-10"
        izz="3.147E-04" />
    </inertial>
  </link>
  <joint name="joint22" type="revolute">
    <parent link="link22"/>
    <child link="link23"/>
    <origin xyz="-0.09 0 0" rpy="-1.570796 0 0"/>
    <axis xyz="0 0 1"/>
    <limit lower="-1.57" upper="1.57" effort="9.2" velocity="1.72"/>
  </joint>
  <link name="link23">
    <visual>
      <geometry>
        <mesh filename="package://snake_sim/share/snake_sim/config/model/meshes/simple_snake_link.stl" scale="1 1 1"/>
      </geometry>
      <material name="yellow">
        <color rgba="1 1 0 1"/>
      </material>
    </visual>
    <collision>
      <origin
        xyz="0 0 0"
        rpy="0 0 0" />
      <geometry>
        <mesh
          filename="package://snake_sim/share/snake_sim/config/model/meshes/simple_snake_link.stl" scale="1 1 1"/>
      </geometry>
    </collision>
    <inertial>
      <origin
        xyz="-0.018 0 0"
        rpy="0 0 0" />
      <mass
        value="0.300" />
      <inertia
        ixx="1.732E-04"
        ixy="0.000"
        ixz="0.000"
        iyy="2.871E-04"
        iyz="2.979E-10"
        izz="3.147E-04" />
    </inertial>
  </link>
  <joint name="joint23" type="revolute">
    <parent link="link23"/>
    <child link="link24"/>
    <origin xyz="-0.09 0 0" rpy="1.570796 0 0"/>
    <axis xyz="0 0 1"/>
    <limit lower="-1.57" upper="1.57" effort="9.2" velocity="1.72"/>
  </joint>
  <link name="link24">
    <visual>
      <geometry>
        <mesh filename="package://snake_sim/share/snake_sim/config/model/meshes/simple_snake_link.stl" scale="1 1 1"/>
      </geometry>
      <material name="green">
        <color rgba="0 1 0 1"/>
      </material>
    </visual>
    <collision>
      <origin
        xyz="0 0 0"
        rpy="0 0 0" />
      <geometry>
        <mesh
          filename="package://snake_sim/share/snake_sim/config/model/meshes/simple_snake_link.stl" scale="1 1 1"/>
      </geometry>
    </collision>
    <inertial>
      <origin
        xyz="-0.018 0 0"
        rpy="0 0 0" />
      <mass
        value="0.300" />
      <inertia
        ixx="1.732E-04"
        ixy="0.000"
        ixz="0.000"
        iyy="2.871E-04"
        iyz="2.979E-10"
        izz="3.147E-04" />
    </inertial>
  </link>
  <joint name="joint24" type="revolute">
    <parent link="link24"/>
    <child link="link25"/>
    <origin xyz="-0.09 0 0" rpy="-1.570796 0 0"/>
    <axis xyz="0 0 1"/>
    <limit lower="-1.57" upper="1.57" effort="9.2" velocity="1.72"/>
  </joint>
  <link name="link25">
    <visual>
      <geometry>
        <mesh filename="package://snake_sim/share/snake_sim/config/model/meshes/simple_snake_link.stl" scale="1 1 1"/>
      </geometry>
      <material name="yellow">
        <color rgba="1 1 0 1"/>
      </material>
    </visual>
    <collision>
      <origin
        xyz="0 0 0"
        rpy="0 0 0" />
      <geometry>
        <mesh
          filename="package://snake_sim/share/snake_sim/config/model/meshes/simple_snake_link.stl" scale="1 1 1"/>
      </geometry>
    </collision>
    <inertial>
      <origin
        xyz="-0.018 0 0"
        rpy="0 0 0" />
      <mass
        value="0.300" />
      <inertia
        ixx="1.732E-04"
        ixy="0.000"
        ixz="0.000"
        iyy="2.871E-04"
        iyz="2.979E-10"
        izz="3.147E-04" />
    </inertial>
  </link>
  <joint name="joint25" type="revolute">
    <parent link="link25"/>
    <child link="link26"/>
    <origin xyz="-0.09 0 0" rpy="1.570796 0 0"/>
    <axis xyz="0 0 1"/>
    <limit lower="-1.57" upper="1.57" effort="9.2" velocity="1.72"/>
  </joint>
  <link name="link26">
    <visual>
      <geometry>
        <mesh filename="package://snake_sim/share/snake_sim/config/model/meshes/simple_snake_link.stl" scale="1 1 1"/>
      </geometry>
      <material name="green">
        <color rgba="0 1 0 1"/>
      </material>
    </visual>
    <collision>
      <origin
        xyz="0 0 0"
        rpy="0 0 0" />
      <geometry>
        <mesh
          filename="package://snake_sim/share/snake_sim/config/model/meshes/simple_snake_link.stl" scale="1 1 1"/>
      </geometry>
    </collision>
    <inertial>
      <origin
        xyz="-0.018 0 0"
        rpy="0 0 0" />
      <mass
        value="0.300" />
      <inertia
        ixx="1.732E-04"
        ixy="0.000"
        ixz="0.000"
        iyy="2.871E-04"
        iyz="2.979E-10"
        izz="3.147E-04" />
    </inertial>
  </link>
  <joint name="joint26" type="revolute">
    <parent link="link26"/>
    <child link="link27"/>
    <origin xyz="-0.09 0 0" rpy="-1.570796 0 0"/>
    <axis xyz="0 0 1"/>
    <limit lower="-1.57" upper="1.57" effort="9.2" velocity="1.72"/>
  </joint>
  <link name="link27">
    <visual>
      <geometry>
        <mesh filename="package://snake_sim/share/snake_sim/config/model/meshes/simple_snake_link.stl" scale="1 1 1"/>
      </geometry>
      <material name="yellow">
        <color rgba="1 1 0 1"/>
      </material>
    </visual>
    <collision>
      <origin
        xyz="0 0 0"
        rpy="0 0 0" />
      <geometry>
        <mesh
          filename="package://snake_sim/share/snake_sim/config/model/meshes/simple_snake_link.stl" scale="1 1 1"/>
      </geometry>
    </collision>
    <inertial>
      <origin
        xyz="-0.018 0 0"
        rpy="0 0 0" />
      <mass
        value="0.300" />
      <inertia
        ixx="1.732E-04"
        ixy="0.000"
        ixz="0.000"
        iyy="2.871E-04"
        iyz="2.979E-10"
        izz="3.147E-04" />
    </inertial>
  </link>
  <joint name="joint27" type="revolute">
    <parent link="link27"/>
    <child link="link28"/>
    <origin xyz="-0.09 0 0" rpy="1.570796 0 0"/>
    <axis xyz="0 0 1"/>
    <limit lower="-1.57" upper="1.57" effort="9.2" velocity="1.72"/>
  </joint>
  <link name="link28">
    <visual>
      <geometry>
        <mesh filename="package://snake_sim/share/snake_sim/config/model/meshes/simple_snake_link.stl" scale="1 1 1"/>
      </geometry>
      <material name="green">
        <color rgba="0 1 0 1"/>
      </material>
    </visual>
    <collision>
      <origin
        xyz="0 0 0"
        rpy="0 0 0" />
      <geometry>
        <mesh
          filename="package://snake_sim/share/snake_sim/config/model/meshes/simple_snake_link.stl" scale="1 1 1"/>
      </geometry>
    </collision>
    <inertial>
      <origin
        xyz="-0.018 0 0"
        rpy="0 0 0" />
      <mass
        value="0.300" />
      <inertia
        ixx="1.732E-04"
        ixy="0.000"
        ixz="0.000"
        iyy="2.871E-04"
        iyz="2.979E-10"
        izz="3.147E-04" />
    </inertial>
  </link>
  <joint name="joint28" type="revolute">
    <parent link="link28"/>
    <child link="link29"/>
    <origin xyz="-0.09 0 0" rpy="-1.570796 0 0"/>
    <axis xyz="0 0 1"/>
    <limit lower="-1.57" upper="1.57" effort="9.2" velocity="1.72"/>
  </joint>
  <link name="link29">
    <visual>
      <geometry>
        <mesh filename="package://snake_sim/share/snake_sim/config/model/meshes/simple_snake_link.stl" scale="1 1 1"/>
      </geometry>
      <material name="yellow">
        <color rgba="1 1 0 1"/>
      </material>
    </visual>
    <collision>
      <origin
        xyz="0 0 0"
        rpy="0 0 0" />
      <geometry>
        <mesh
          filename="package://snake_sim/share/snake_sim/config/model/meshes/simple_snake_link.stl" scale="1 1 1"/>
      </geometry>
    </collision>
    <inertial>
      <origin
        xyz="-0.018 0 0"
        rpy="0 0 0" />
      <mass
        value="0.300" />
      <inertia
        ixx="1.732E-04"
        ixy="0.000"
        ixz="0.000"
        iyy="2.871E-04"
        iyz="2.979E-10"
        izz="3.147E-04" />
    </inertial>
  </link>
  <joint name="joint29" type="revolute">
    <parent link="link29"/>
    <child link="link30"/>
    <origin xyz="-0.09 0 0" rpy="1.570796 0 0"/>
    <axis xyz="0 0 1"/>
    <limit lower="-1.57" upper="1.57" effort="9.2" velocity="1.72"/>
  </joint>
  <link name="link30">
    <visual>
      <geometry>
        <mesh filename="package://snake_sim/share/snake_sim/config/model/meshes/simple_snake_link.stl" scale="1 1 1"/>
      </geometry>
      <material name="green">
        <color rgba="0 1 0 1"/>
      </material>
    </visual>
    <collision>
      <origin
        xyz="0 0 0"
        rpy="0 0 0" />
      <geometry>
        <mesh
          filename="package://snake_sim/share/snake_sim/config/model/meshes/simple_snake_link.stl" scale="1 1 1"/>
      </geometry>
    </collision>
    <inertial>
      <origin
        xyz="-0.018 0 0"
        rpy="0 0 0" />
      <mass
        value="0.300" />
      <inertia
        ixx="1.732E-04"
        ixy="0.000"
        ixz="0.000"
        iyy="2.871E-04"
        iyz="2.979E-10"
        izz="3.147E-04" />
    </inertial>
  </link>
  <joint name="joint30" type="revolute">
    <parent link="link30"/>
    <child link="link31"/>
    <origin xyz="-0.09 0 0" rpy="-1.570796 0 0"/>
    <axis xyz="0 0 1"/>
    <limit lower="-1.57" upper="1.57" effort="9.2" velocity="1.72"/>
  </joint>
  <link name="link31">
    <visual>
      <geometry>
        <mesh filename="package://snake_sim/share/snake_sim/config/model/meshes/simple_snake_link.stl" scale="1 1 1"/>
      </geometry>
      <material name="yellow">
        <color rgba="1 1 0 1"/>
      </material>
    </visual>
    <collision>
      <origin
        xyz="0 0 0"
        rpy="0 0 0" />
      <geometry>
        <mesh
          filename="package://snake_sim/share/snake_sim/config/model/meshes/simple_snake_link.stl" scale="1 1 1"/>
      </geometry>
    </collision>
    <inertial>
      <origin
        xyz="-0.018 0 0"
        rpy="0 0 0" />
      <mass
        value="0.300" />
      <inertia
        ixx="1.732E-04"
        ixy="0.000"
        ixz="0.000"
        iyy="2.871E-04"
        iyz="2.979E-10"
        izz="3.147E-04" />
    </inertial>
  </link>
  <joint name="joint31" type="revolute">
    <parent link="link31"/>
    <child link="link32"/>
    <origin xyz="-0.09 0 0" rpy="1.570796 0 0"/>
    <axis xyz="0 0 1"/>
    <limit lower="-1.57" upper="1.57" effort="9.2" velocity="1.72"/>
  </joint>
  <link name="link32">
    <visual>
      <geometry>
        <mesh filename="package://snake_sim/share/snake_sim/config/model/meshes/simple_snake_link.stl" scale="1 1 1"/>
      </geometry>
      <material name="green">
        <color rgba="0 1 0 1"/>
      </material>
    </visual>
    <collision>
      <origin
        xyz="0 0 0"
        rpy="0 0 0" />
      <geometry>
        <mesh
          filename="package://snake_sim/share/snake_sim/config/model/meshes/simple_snake_link.stl" scale="1 1 1"/>
      </geometry>
    </collision>
    <inertial>
      <origin
        xyz="-0.018 0 0"
        rpy="0 0 0" />
      <mass
        value="0.300" />
      <inertia
        ixx="1.732E-04"
        ixy="0.000"
        ixz="0.000"
        iyy="2.871E-04"
        iyz="2.979E-10"
        izz="3.147E-04" />
    </inertial>
  </link>
  <joint name="joint32" type="revolute">
    <parent link="link32"/>
    <child link="link33"/>
    <origin xyz="-0.09 0 0" rpy="-1.570796 0 0"/>
    <axis xyz="0 0 1"/>
    <limit lower="-1.57" upper="1.57" effort="9.2" velocity="1.72"/>
  </joint>
  <link name="link33">
    <visual>
      <geometry>
        <mesh filename="package://snake_sim/share/snake_sim/config/model/meshes/simple_snake_link.stl" scale="1 1 1"/>
      </geometry>
      <material name="yellow">
        <color rgba="1 1 0 1"/>
      </material>
    </visual>
    <collision>
      <origin
        xyz="0 0 0"
        rpy="0 0 0" />
      <geometry>
        <mesh
          filename="package://snake_sim/share/snake_sim/config/model/meshes/simple_snake_link.stl" scale="1 1 1"/>
      </geometry>
    </collision>
    <inertial>
      <origin
        xyz="-0.018 0 0"
        rpy="0 0 0" />
      <mass
        value="0.300" />
      <inertia
        ixx="1.732E-04"
        ixy="0.000"
        ixz="0.000"
        iyy="2.871E-04"
        iyz="2.979E-10"
        izz="3.147E-04" />
    </inertial>
  </link>
</robot>