<?xml version="1.0"?>
<robot name="simple_robot">
  <!-- ベースリンク -->
  <link name="base_link">
    <visual>
      <geometry>
        <box size="0.001 0.001 0.001"/>
      </geometry>
      <material name="red">
        <color rgba="1 0 0 1"/>
      </material>
    </visual>
  </link>
  <joint name="joint_base" type="fixed">
    <parent link="base_link"/>
    <child link="body_link"/>
    <origin xyz="0 0 0.3" rpy="0 0 0"/>
    <axis xyz="0 0 0"/>
  </joint>
  
  <link name="body_link">
    <visual>
      <geometry>
        <box size="0.2 0.2 0.1" />
      </geometry>
      <material name="red">
        <color rgba="1 0 0 1"/>
      </material>
    </visual>
    <collision>
      <origin
        xyz="0 0 0"
        rpy="0 0 0" />
      <geometry>
        <box size="0.2 0.2 0.1" />
      </geometry>
    </collision>
    <inertial>
      <origin
        xyz="0 0 0"
        rpy="0 0 0" />
      <mass
        value="0.500" />
      <inertia
        ixx="0.0020833" ixy="0.0" ixz="0.0"
        iyy="0.0020833" iyz="0.0"
        izz="0.0033333" />
    </inertial>
  </link>
  <joint name="joint_l" type="revolute">
    <parent link="body_link"/>
    <child link="wheel_l"/>
    <origin xyz="0 0.13 0" rpy="1.570796 0 0"/>
    <axis xyz="0 0 1"/>
    <limit lower="-1.0e+10" upper="1.0e+10" effort="10.0" velocity="100.0"/>
  </joint>
  <link name="wheel_l">
    <visual>
      <geometry>
        <cylinder length="0.05" radius="0.075"/>
      </geometry>
      <material name="green">
        <color rgba="0 1 0 1"/>
      </material>
    </visual>
    <collision>
      <origin
        xyz="0 0 0"
        rpy="0 0 0" />
      <geometry>
        <cylinder length="0.05" radius="0.075"/>
      </geometry>
    </collision>
    <inertial>
      <origin
        xyz="0 0 0"
        rpy="0 0 0" />
      <mass
        value="0.100" />
      <inertia
        ixx="0.00016146" ixy="0.0" ixz="0.0"
        iyy="0.00016146" iyz="0.0"
        izz="0.00028125" />
    </inertial>
  </link>
  <joint name="joint_r" type="revolute">
    <parent link="body_link"/>
    <child link="wheel_r"/>
    <origin xyz="0 -0.13 0" rpy="-1.570796 0 0"/>
    <axis xyz="0 0 1"/>
    <limit lower="-1.0e+10" upper="1.0e+10" effort="10.0" velocity="100.0"/>
  </joint>
  <link name="wheel_r">
    <visual>
      <geometry>
        <cylinder length="0.05" radius="0.075"/>
      </geometry>
      <material name="blue">
        <color rgba="0 0 1 1"/>
      </material>
    </visual>
    <collision>
      <origin
        xyz="0 0 0"
        rpy="0 0 0" />
      <geometry>
        <cylinder length="0.05" radius="0.075"/>
      </geometry>
    </collision>
    <inertial>
      <origin
        xyz="0 0 0"
        rpy="0 0 0" />
      <mass
        value="0.100" />
      <inertia
        ixx="0.00016146" ixy="0.0" ixz="0.0"
        iyy="0.00016146" iyz="0.0"
        izz="0.00028125" />
    </inertial>
  </link>
</robot>